<?xml version="1.0"?>
<robot name="GroundsBot" xmlns:xacro="http://www.ros.org/wiki/xacro">

  <!-- Xacro properties -->
  <xacro:property name="width" value="3.0"/>
  <xacro:property name="height" value="1.5"/>
  <xacro:property name="length" value="4.5"/>
  <xacro:property name="wheel_radius" value="0.7"/>
  <xacro:property name="wheel_width" value="0.6"/>

  <!-- Colors -->
  <material name="grey">
    <color rgba="0.7 0.7 0.7 1.0"/>
  </material>
  <material name="black">
    <color rgba="0.1 0.1 0.1 1.0"/>
  </material>
  <material name="red">
    <color rgba="0.8 0.1 0.1 1.0"/>
  </material>
  
  <!-- Xacro macros -->
  <xacro:macro name="wheel" params="prefix">
    <link name="${prefix}_wheel_link">
      <visual>
        <origin xyz="0 0 0" rpy="${pi/2} 0 0"/>
        <geometry>
          <cylinder radius="${wheel_radius}" length="${wheel_width}"/>
        </geometry>
        <material name="black"/>
      </visual>
    </link>
  </xacro:macro>

  <!-- Links -->
  <link name="base_link">
    <visual>
      <origin xyz="0 0 ${height / 2}" rpy="0 0 0"/>
      <geometry>
        <box size="${(length / 3) * 2} ${width - (wheel_width * 2)} ${height}"/>
      </geometry>
      <material name="grey"/>
    </visual>
  </link>
  <link name="cutting_unit_link">
    <visual>
      <origin xyz="${length / 6} 0 ${height / 6}" rpy="0 0 0"/>
      <geometry>
        <box size="${length / 3} ${width} ${height / 3}"/>
      </geometry>
      <material name="grey"/>
    </visual>
  </link>
  <xacro:wheel prefix="front_left"/>
  <xacro:wheel prefix="rear_left"/>
  <xacro:wheel prefix="front_right"/>
  <xacro:wheel prefix="rear_right"/>
  
  <!-- Joints -->
  <joint name="base_cutting_unit_joint" type="fixed">
    <parent link="base_link"/>
    <child link="cutting_unit_link"/>
    <origin xyz="${length / 3} 0 0" rpy="0 0 0"/>
  </joint>
  <joint name="base_front_left_wheel_joint" type="continuous">
    <parent link="base_link"/>
    <child link="front_left_wheel_link"/>
    <origin xyz="${length / 6} ${(width - wheel_width) / -2} 0" rpy="0 0 0"/>
    <axis xyz="0 1 0"/>
  </joint>
  <joint name="base_rear_left_wheel_joint" type="continuous">
    <parent link="base_link"/>
    <child link="rear_left_wheel_link"/>
    <origin xyz="${length / -6} ${(width - wheel_width) / -2} 0" rpy="0 0 0"/>
    <axis xyz="0 1 0"/>
  </joint>
  <joint name="base_front_right_wheel_joint" type="continuous">
    <parent link="base_link"/>
    <child link="front_right_wheel_link"/>
    <origin xyz="${length / 6} ${(width - wheel_width) / 2} 0" rpy="0 0 0"/>
    <axis xyz="0 1 0"/>
  </joint>
  <joint name="base_rear_right_wheel_joint" type="continuous">
    <parent link="base_link"/>
    <child link="rear_right_wheel_link"/>
    <origin xyz="${length / -6} ${(width - wheel_width) / 2} 0" rpy="0 0 0"/>
    <axis xyz="0 1 0"/>
  </joint>

</robot>

<!-- <collision>
      <origin xyz="0 0 0" rpy="0 0 0"/>
      <geometry>
        <box size="2.0 1.2 0.4"/>
      </geometry>
    </collision>

    <inertial>
      <origin xyz="0 0 0" rpy="0 0 0"/>
      <mass value="200.0"/>
      <inertia ixx="16.0" iyy="66.7" izz="80.7" ixy="0" ixz="0" iyz="0"/>
    </inertial> -->

